Traceback (most recent call last):
  File "C:\Users\dbigman\AppData\Local\uv\cache\archive-v0\hpwd_WbV3FgHGH7IgeaMT\Lib\site-packages\mcp_server_redis\server.py", line 13, in <module>
    settings = RedisSettings()
               ^^^^^^^^^^^^^^^
  File "C:\Users\dbigman\AppData\Local\uv\cache\archive-v0\hpwd_WbV3FgHGH7IgeaMT\Lib\site-packages\pydantic_settings\main.py", line 193, in __init__
    super().__init__(
  File "C:\Users\dbigman\AppData\Local\uv\cache\archive-v0\hpwd_WbV3FgHGH7IgeaMT\Lib\site-packages\pydantic\main.py", line 253, in __init__
    validated_self = self.__pydantic_validator__.validate_python(data, self_instance=self)
                     ^^^^^^^^^^^^^^^^^^^^^^^^^^^^^^^^^^^^^^^^^^^^^^^^^^^^^^^^^^^^^^^^^^^^^
pydantic_core._pydantic_core.ValidationError: 4 validation errors for RedisSettings
REDIS_HOST
  Field required [type=missing, input_value={}, input_type=dict]
    For further information visit https://errors.pydantic.dev/2.11/v/missing
REDIS_PORT
  Field required [type=missing, input_value={}, input_type=dict]
    For further information visit https://errors.pydantic.dev/2.11/v/missing
REDIS_DB
  Field required [type=missing, input_value={}, input_type=dict]
    For further information visit https://errors.pydantic.dev/2.11/v/missing
REDIS_PASSWORD
  Field required [type=missing, input_value={}, input_type=dict]
    For further information visit https://errors.pydantic.dev/2.11/v/missing

During handling of the above exception, another exception occurred:

Traceback (most recent call last):
  File "<frozen runpy>", line 198, in _run_module_as_main
  File "<frozen runpy>", line 88, in _run_code
  File "C:\Users\dbigman\AppData\Local\uv\cache\archive-v0\hpwd_WbV3FgHGH7IgeaMT\Scripts\mcp-server-redis.exe\__main__.py", line 4, in <module>
  File "C:\Users\dbigman\AppData\Local\uv\cache\archive-v0\hpwd_WbV3FgHGH7IgeaMT\Lib\site-packages\mcp_server_redis\__init__.py", line 1, in <module>
    from mcp_server_redis.server import mcp
  File "C:\Users\dbigman\AppData\Local\uv\cache\archive-v0\hpwd_WbV3FgHGH7IgeaMT\Lib\site-packages\mcp_server_redis\server.py", line 15, in <module>
    raise ValueError(f"Failed to load Redis settings: {e}")
ValueError: Failed to load Redis settings: 4 validation errors for RedisSettings
REDIS_HOST
  Field required [type=missing, input_value={}, input_type=dict]
    For further information visit https://errors.pydantic.dev/2.11/v/missing
REDIS_PORT
  Field required [type=missing, input_value={}, input_type=dict]
    For further information visit https://errors.pydantic.dev/2.11/v/missing
REDIS_DB
  Field required [type=missing, input_value={}, input_type=dict]
    For further information visit https://errors.pydantic.dev/2.11/v/missing
REDIS_PASSWORD
  Field required [type=missing, input_value={}, input_type=dict]
    For further information visit https://errors.pydantic.dev/2.11/v/missing
